Workbook

Sheet Entrada de Dados
B2: Sensory Processing Measure
B9: Informações Gerais
B11: Nome/No Identificação:
B12: Relacionamento com a criança:
B13: Data:
B14: Sexo da criança: M/F
B15: Idade: __ anos __ meses
B16: Raça/Etnia:
B17: Comentários sobre comportamento e funcionamento da criança:
B19: INSTRUÇÕES: Por favor, responda as perguntas deste formulário com base no comportamento típico da sua criança durante o mês passado. Use a seguinte escala de avaliação: Nunca: O comportamento nunca ou quase nunca acontece. Frequentemente: O comportamento ocorre grande parte do tempo. Ocasionalmente: O comportamento ocorre algumas vezes. Sempre: A criança sempre ou quase sempre responde dessa maneira. Circule uma das respostas que melhor descreve com que frequência o comportamento acontece. Faça o seu melhor para responder todas as questões. Várias questões perguntam se a criança se mostra desconfortável em determinadas situações. Mostrar-se desconfortável pode incluir expressões verbais (resmungar, chorar, gritar) ou expressões não verbais (afastar-se, gesticular, empurrar algo para longe, fugir, encolher-se, derrubar/arremessar objetos). Você poderá usar o espaço a esquerda para adicionar qualquer comentário sobre o comportamento ou funcionamento de sua criança.
B29: Categorias e Itens Avaliados
B31: 1. Participação Social
C32: 4 | D32: 3 | E32: 2 | F32: 1
B33: Esta criança: | C33: Nunca | D33: Ocasional | E33: Frequente | F33: Sempre
B34: 1.Sabe trabalhar em grupo; é solícito com outros. | C34: FALSE | D34: FALSE | E34: FALSE | F34: TRUE
B35: 2.Resolve conflitos com colegas sem a intervenção do professor. | C35: FALSE | D35: TRUE | E35: FALSE | F35: FALSE
B36: 3.Lida com frustrações sem explosões ou comportamento agressivo. | C36: FALSE | D36: TRUE | E36: FALSE | F36: FALSE
B37: 4.Participa espontaneamente com colegas em uma variedade de jogos e atividades. | C37: FALSE | D37: FALSE | E37: TRUE | F37: FALSE
B38: 5.Participa da brincadeira sem interromper seu andamento. | C38: FALSE | D38: TRUE | E38: FALSE | F38: FALSE
B39: 6.Tem amigos e escolhe estar com eles quando possível. | C39: FALSE | D39: FALSE | E39: FALSE | F39: TRUE
B40: 7.Compreende e usa de humor quando brinca com amigos. | C40: FALSE | D40: FALSE | E40: FALSE | F40: TRUE
B41: 8.Mantém apropriadamente seu "espaço pessoal" (não fica muito próximo quando conversa). | C41: FALSE | D41: FALSE | E41: FALSE | F41: TRUE
B42: 9.Mantém contato visual apropriado durante a conversa. | C42: FALSE | D42: FALSE | E42: FALSE | F42: TRUE
B43: 10.Muda os tópicos das conversas de acordo com o interesse dos colegas; não fica preso a um tópico só. | C43: FALSE | D43: FALSE | E43: TRUE | F43: FALSE
B44: SCORE | C44: =COUNTIF(C34:C43,"=true")*C32 -> 0 | D44: =COUNTIF(D34:D43,"=true")*D32 -> 9 | E44: =COUNTIF(E34:E43,"=true")*E32 -> 4 | F44: =COUNTIF(F34:F43,"=true")*F32 -> 5 | G44: =SUM(C44:F44) -> 18
B46: 2. Visão
C47: 1 | D47: 2 | E47: 3 | F47: 4
B48: Esta criança: | C48: Nunca | D48: Ocasional | E48: Frequente | F48: Sempre
B49: 11.Aperta, cobre os olhos ou reclama da claridade da sala de aula ou o brilho do sol. | C49: TRUE | D49: FALSE | E49: FALSE | F49: FALSE
B50: 12.Fica incomodado com o movimento de objetos. | C50: TRUE | D50: FALSE | E50: FALSE | F50: FALSE
B51: 13.Se distrai com estímulo visual próximo (figuras, objetos em estantes, janelas, outras crianças). | C51: TRUE | D51: FALSE | E51: FALSE | F51: FALSE
B52: 14.Durante a instrução ou um anúncio, olha ao redor ou para os colegas ao invés de olhar para a pessoa que fala ou para o quadro negro. | C52: TRUE | D52: FALSE | E52: FALSE | F52: FALSE
B53: 15.Gira ou movimenta subitamente objetos em frente aos olhos. | C53: TRUE | D53: FALSE | E53: FALSE | F53: FALSE
B54: 16.Olha fixamente para pessoas ou objetos. | C54: TRUE | D54: FALSE | E54: FALSE | F54: FALSE
B55: 17.Fica incomodado quando as luzes diminuem no cinema ou teatro. | C55: TRUE | D55: FALSE | E55: FALSE | F55: FALSE
B56: SCORE | C56: =COUNTIF(C49:C55,"=true")*C47 -> 7 | D56: =COUNTIF(D49:D55,"=true")*D47 -> 0 | E56: =COUNTIF(E49:E55,"=true")*E47 -> 0 | F56: =COUNTIF(F49:F55,"=true")*F47 -> 0 | G56: =SUM(C56:F56) -> 7
B58: 3. Audição
C59: 1 | D59: 2 | E59: 3 | F59: 4
B60: Esta criança: | C60: Nunca | D60: Ocasional | E60: Frequente | F60: Sempre
B61: 18.Se incomoda com sons altos (batidas de portas, furadeiras, apontador elétrico). | C61: TRUE | D61: FALSE | E61: FALSE | F61: FALSE
...

Sheet Plano
B2: PLANO | C2: ITEM
B3: =IF(COUNTIF(B4:B13,"=TRUE")>0,TRUE,FALSE) -> FALSE | C3: 1. Participação Social
B4: {=VLOOKUP(C4:C4,'Entrada de Dados'!$B$34:$F$43,2)} -> FALSE | C4: ='Entrada de Dados'!B34 -> 1.Sabe trabalhar em grupo; é solícito com outros.
B5: {=VLOOKUP(C5:C5,'Entrada de Dados'!$B$34:$F$43,2)} -> FALSE | C5: ='Entrada de Dados'!B35 -> 2.Resolve conflitos com colegas sem a intervenção do professor.
B6: {=VLOOKUP(C6:C6,'Entrada de Dados'!$B$34:$F$43,2)} -> FALSE | C6: ='Entrada de Dados'!B36 -> 3.Lida com frustrações sem explosões ou comportamento agressivo.
B7: {=VLOOKUP(C7:C7,'Entrada de Dados'!$B$34:$F$43,2)} -> FALSE | C7: ='Entrada de Dados'!B37 -> 4.Participa espontaneamente com colegas em uma variedade de jogos e atividades.
B8: {=VLOOKUP(C8:C8,'Entrada de Dados'!$B$34:$F$43,2)} -> FALSE | C8: ='Entrada de Dados'!B38 -> 5.Participa da brincadeira sem interromper seu andamento.
B9: {=VLOOKUP(C9:C9,'Entrada de Dados'!$B$34:$F$43,2)} -> FALSE | C9: ='Entrada de Dados'!B39 -> 6.Tem amigos e escolhe estar com eles quando possível.
B10: {=VLOOKUP(C10:C10,'Entrada de Dados'!$B$34:$F$43,2)} -> FALSE | C10: ='Entrada de Dados'!B40 -> 7.Compreende e usa de humor quando brinca com amigos.
B11: {=VLOOKUP(C11:C11,'Entrada de Dados'!$B$34:$F$43,2)} -> FALSE | C11: ='Entrada de Dados'!B41 -> 8.Mantém apropriadamente seu "espaço pessoal" (não fica muito próximo quando conversa).
B12: {=VLOOKUP(C12:C12,'Entrada de Dados'!$B$34:$F$43,2)} -> FALSE | C12: ='Entrada de Dados'!B42 -> 9.Mantém contato visual apropriado durante a conversa.
B13: {=VLOOKUP(C13:C13,'Entrada de Dados'!$B$34:$F$43,2)} -> FALSE | C13: ='Entrada de Dados'!B43 -> 10.Muda os tópicos das conversas de acordo com o interesse dos colegas; não fica preso a um tópico só.
B15: =IF(COUNTIF(B16:B22,"=TRUE")>0,TRUE,FALSE) -> FALSE | C15: 2. Visão
B16: {=VLOOKUP(C16:C16,'Entrada de Dados'!$B$49:$F$55,5)} -> FALSE | C16: ='Entrada de Dados'!B49 -> 11.Aperta, cobre os olhos ou reclama da claridade da sala de aula ou o brilho do sol.
B17: {=VLOOKUP(C17:C17,'Entrada de Dados'!$B$49:$F$55,5)} -> FALSE | C17: ='Entrada de Dados'!B50 -> 12.Fica incomodado com o movimento de objetos.
B18: {=VLOOKUP(C18:C18,'Entrada de Dados'!$B$49:$F$55,5)} -> FALSE | C18: ='Entrada de Dados'!B51 -> 13.Se distrai com estímulo visual próximo (figuras, objetos em estantes, janelas, outras crianças).
B19: {=VLOOKUP(C19:C19,'Entrada de Dados'!$B$49:$F$55,5)} -> FALSE | C19: ='Entrada de Dados'!B52 -> 14.Durante a instrução ou um anúncio, olha ao redor ou para os colegas ao invés de olhar para a pessoa que fala ou para o quadro negro.
B20: {=VLOOKUP(C20:C20,'Entrada de Dados'!$B$49:$F$55,5)} -> FALSE | C20: ='Entrada de Dados'!B53 -> 15.Gira ou movimenta subitamente objetos em frente aos olhos.
B21: {=VLOOKUP(C21:C21,'Entrada de Dados'!$B$49:$F$55,5)} -> FALSE | C21: ='Entrada de Dados'!B54 -> 16.Olha fixamente para pessoas ou objetos.
B22: {=VLOOKUP(C22:C22,'Entrada de Dados'!$B$49:$F$55,5)} -> FALSE | C22: ='Entrada de Dados'!B55 -> 17.Fica incomodado quando as luzes diminuem no cinema ou teatro.
B24: =IF(COUNTIF(B25:B31,"=TRUE")>0,TRUE,FALSE) -> FALSE | C24: 3. Audição
B25: {=VLOOKUP(C25:C25,'Entrada de Dados'!$B$61:$F$67,5)} -> FALSE | C25: ='Entrada de Dados'!B61 -> 18.Se incomoda com sons altos (batidas de portas, furadeiras, apontador elétrico).
B26: {=VLOOKUP(C26:C26,'Entrada de Dados'!$B$61:$F$67,5)} -> FALSE | C26: ='Entrada de Dados'!B62 -> 19.Se incomoda com o som de música ou instrumentos musicais.
B27: {=VLOOKUP(C27:C27,'Entrada de Dados'!$B$61:$F$67,5)} -> FALSE | C27: ='Entrada de Dados'!B63 -> 20.Não responde a vozes ou novos sons.
B28: {=VLOOKUP(C28:C28,'Entrada de Dados'!$B$61:$F$67,5)} -> FALSE | C28: ='Entrada de Dados'!B64 -> 21.Não consegue determinar a localização de vozes ou sons.
B29: {=VLOOKUP(C29:C29,'Entrada de Dados'!$B$61:$F$67,5)} -> FALSE | C29: ='Entrada de Dados'!B65 -> 22.Faz barulhos, assobia, canta ou grita enquanto a classe está em silêncio.
B30: {=VLOOKUP(C30:C30,'Entrada de Dados'!$B$61:$F$67,5)} -> FALSE | C30: ='Entrada de Dados'!B66 -> 23.Fala muito alto ou faz muito barulho durante o recreio.
B31: {=VLOOKUP(C31:C31,'Entrada de Dados'!$B$61:$F$67,5)} -> FALSE | C31: ='Entrada de Dados'!B67 -> 24.Grita, berra ou produz barulhos incomuns sozinho.
B33: =IF(COUNTIF(B34:B41,"=TRUE")>0,TRUE,FALSE) -> FALSE | C33: 4. Tato
B34: {=VLOOKUP(C34:C34,'Entrada de Dados'!$B$73:$F$80,5)} -> FALSE | C34: ='Entrada de Dados'!B73 -> 25.Fica incomodado quando as mãos ou rosto estão sujos (com cola, pintura a dedo, comida, sujeira, etc).
B35: {=VLOOKUP(C35:C35,'Entrada de Dados'!$B$73:$F$80,5)} -> FALSE | C35: ='Entrada de Dados'!B74 -> 26.Não tolera sujeira nas mãos ou na roupa, mesmo que brevemente.
B36: {=VLOOKUP(C36:C36,'Entrada de Dados'!$B$73:$F$80,5)} -> FALSE | C36: ='Entrada de Dados'!B75 -> 27.Demonstra desconforto ao tocar determinadas texturas (materiais escolares, utensílios, equipamentos esportivos, etc.).
B37: {=VLOOKUP(C37:C37,'Entrada de Dados'!$B$73:$F$80,5)} -> FALSE | C37: ='Entrada de Dados'!B76 -> 28.Fica incomodado com o contato acidental dos amigos (pode revidar ou sair de perto).
B38: {=VLOOKUP(C38:C38,'Entrada de Dados'!$B$73:$F$80,5)} -> FALSE | C38: ='Entrada de Dados'!B77 -> 29.Não responde ao toque de outra pessoa.
B39: {=VLOOKUP(C39:C39,'Entrada de Dados'!$B$73:$F$80,5)} -> FALSE | C39: ='Entrada de Dados'!B78 -> 30.Procura pela temperatura quente ou fria ao tocar janela ou outras superfícies.
B40: {=VLOOKUP(C40:C40,'Entrada de Dados'!$B$73:$F$80,5)} -> FALSE | C40: ='Entrada de Dados'!B79 -> 31.Toca inapropriadamente os colegas durante a aula ou em fila.
B41: {=VLOOKUP(C41:C41,'Entrada de Dados'!$B$73:$F$80,5)} -> FALSE | C41: ='Entrada de Dados'!B80 -> 32.Não limpa a saliva ou o alimento do rosto.
B43: =IF(COUNTIF(B44:B47,"=TRUE")>0,TRUE,FALSE) -> FALSE | C43: 5. Olfato e Paladar
B44: {=VLOOKUP(C44:C44,'Entrada de Dados'!$B$86:$F$89,5)} -> FALSE | C44: ='Entrada de Dados'!B86 -> 33.Se sente incomodado com o gosto e cheiro de comidas diferentes.
B45: {=VLOOKUP(C45:C45,'Entrada de Dados'!$B$86:$F$89,5)} -> FALSE | C45: ='Entrada de Dados'!B87 -> 34.Não percebe cheiros fortes ou diferentes (cola, tinta, marcadores de texto, etc.).
...

Sheet Gráfico
B2: SCORES - SPM ESCOLA
C3: TOTAL
B4: SOC | C4: VIS | D4: HEA | E4: TOU | F4: BOD | G4: BAL | H4: PLA | I4: TOT
A5: FILIPE MORAES SILVA | B5: ='Entrada de Dados'!G44 -> 18 | C5: ='Entrada de Dados'!G56 -> 7 | D5: ='Entrada de Dados'!G68 -> 7 | E5: ='Entrada de Dados'!G81 -> 8 | F5: ='Entrada de Dados'!G102 -> 8 | G5: ='Entrada de Dados'!G116 -> 12 | H5: ='Entrada de Dados'!G131 -> 11 | I5: =SUM(C5:G5)++'Entrada de Dados'!G90 -> 45
A6: DISFUNÇÃO DEFINITIVA | B6: 32 | C6: 16 | D6: 16 | E6: 16 | F6: 19 | G6: 22 | H6: 28 | I6: =SUM(C6:G6) -> 89
A7: PROVÁVEL DISFUNÇÃO | B7: 21 | C7: 23 | D7: 12 | E7: 11 | F7: 12 | G7: 15 | H7: 19 | I7: =SUM(C7:G7) -> 73
A8: TÍPICO | B8: 22 | C8: 11 | D8: 10 | E8: 10 | F8: 11 | G8: 14 | H8: 18 | I8: =SUM(C8:G8) -> 56

Sheet TAB. REFERÊNCIA
C3: %TILE | D3: T | E3: SOC | F3: VIS | G3: HEA | H3: TOU | I3: BOD | J3: BAL | K3: PLA | L3: TOT | M3: T | N3: %TILE
B4: DISFUNÇÃO DEFINITIVA | D4: 80 | E4: 39-40 | F4: 35-44 | G4: 29-32 | H4: 37-44 | I4: 36-40 | J4: 35-44 | K4: 33-36 | L4: 170-224 | M4: 80
D5: 79 | F5: 33-34 | G5: 27-28 | H5: 36 | I5: 34-35 | J5: 34 | K5: 31-32 | L5: 164-169 | M5: 79
D6: 78 | E6: 38 | F6: 32 | G6: 26 | H6: 34-35 | I6: 33 | J6: 33 | L6: 154-163 | M6: 78
D7: 77 | E7: 37 | F7: 31 | G7: 25 | H7: 33 | I7: 32 | J7: 31-32 | K7: 30 | L7: 142-153 | M7: 77
D8: 76 | E8: 36 | F8: 30 | G8: 23 | I8: 31 | J8: 29-30 | L8: 140-141 | M8: 76
D9: 75 | F9: 28-29 | G9: 22 | H9: 32 | I9: 30 | J9: 27-28 | K9: 29 | L9: 137-139 | M9: 75
C10: >99 | D10: 74 | F10: 27 | H10: 30-31 | I10: 29 | J10: 26 | K10: 28 | L10: 133-136 | M10: 74 | N10: >99
C11: 99 | D11: 73 | E11: 31 | G11: 21 | H11: 28-29 | I11: 28 | K11: 27 | L11: 131-132 | M11: 73 | N11: 99
D12: 72 | F12: 26 | G12: 20 | H12: 27 | I12: 27 | J12: 25 | K12: 26 | L12: 129-130 | M12: 72
C13: 98 | D13: 71 | E13: 30 | F13: 25 | G13: 19 | H13: 26 | I13: 26 | J13: 24 | L13: 122-128 | M13: 71 | N13: 98
D14: 70 | E14: 29 | F14: 24 | I14: 25 | K14: 25 | L14: 119-121 | M14: 70
B15: PROVÁVEL DISFUNÇÃO | C15: 97 | D15: 69 | E15: 28 | F15: 23 | G15: 18 | H15: 25 | I15: 24 | J15: 23 | K15: 24 | L15: 110-115 | M15: 69 | N15: 97
C16: 96 | D16: 68 | F16: 21-22 | G16: 17 | H16: 23-24 | I16: 23 | J16: 22 | L16: 106-109 | M16: 68 | N16: 96
D17: 67 | E17: 27 | F17: 20 | G17: 16 | H17: 22 | I17: 22 | K17: 23 | L17: 103-105 | M17: 67
C18: 95 | D18: 66 | E18: 26 | G18: 15 | H18: 21 | I18: 21 | J18: 21 | K18: 22 | L18: 99-102 | M18: 66 | N18: 95
C19: 93 | D19: 65 | E19: 25 | F19: 19 | H19: 20 | I19: 20 | J19: 20 | K19: 21 | L19: 94-98 | M19: 65 | N19: 93
C20: 92 | D20: 64 | E20: 24 | F20: 18 | G20: 14 | H20: 19 | I20: 19 | J20: 19 | K20: 20 | L20: 92-93 | M20: 64 | N20: 92
C21: 90 | D21: 63 | E21: 23 | F21: 17 | G21: 13 | H21: 18 | I21: 18 | J21: 18 | K21: 19 | L21: 89-91 | M21: 63 | N21: 90
C22: 88 | D22: 62 | E22: 22 | G22: 12 | L22: 84-87 | M22: 62 | N22: 88
C23: 86 | D23: 61 | F23: 16 | H23: 17 | I23: 17 | J23: 17 | K23: 18 | L23: 81-83 | M23: 61 | N23: 86
C24: 84 | D24: 60 | E24: 21 | I24: 16 | K24: 17 | L24: 79-80 | M24: 60 | N24: 84
B25: TÍPICO | C25: 82 | D25: 59 | F25: 15 | G25: 11 | H25: 16 | I25: 15 | J25: 16 | L25: 77-78 | M25: 59 | N25: 82
C26: 79 | D26: 58 | E26: 20 | K26: 16 | L26: 75-76 | M26: 58 | N26: 79
C27: 76 | D27: 57 | F27: 14 | H27: 15 | I27: 14 | J27: 15 | K27: 15 | L27: 73-74 | M27: 57 | N27: 76
C28: 73 | D28: 56 | E28: 19 | G28: 10 | L28: 71-72 | M28: 56 | N28: 73
C29: 69 | D29: 55 | E29: 18 | H29: 14 | I29: 13 | K29: 14 | L29: 70 | M29: 55 | N29: 69
C30: 66 | D30: 54 | F30: 13 | J30: 14 | L30: 69 | M30: 54 | N30: 66
C31: 62 | D31: 53 | E31: 17 | K31: 13 | L31: 67-68 | M31: 53 | N31: 62
C32: 58 | D32: 52 | G32: 9 | H32: 13 | I32: 12 | L32: 66 | M32: 52 | N32: 58
C33: 54 | D33: 51 | E33: 16 | J33: 13 | K33: 12 | L33: 65 | M33: 51 | N33: 54
C34: 50 | D34: 50 | F34: 12 | L34: 64 | M34: 50 | N34: 50
C35: 46 | D35: 49 | E35: 15 | M35: 49 | N35: 46
C36: 42 | D36: 48 | I36: 11 | K36: 11 | L36: 63 | M36: 48 | N36: 42
C37: 38 | D37: 47 | E37: 14 | H37: 12 | J37: 12 | L37: 62 | M37: 47 | N37: 38
C38: 34 | D38: 46 | L38: 61 | M38: 46 | N38: 34
C39: 31 | D39: 45 | E39: 13 | K39: 10 | M39: 45 | N39: 31
C40: 27 | D40: 44 | L40: 60 | M40: 44 | N40: 27
C41: 24 | D41: 43 | E41: 12 | G41: 8 | M41: 43 | N41: 24
C42: 21 | D42: 42 | L42: 59 | M42: 42 | N42: 21
...
